<?xml version="1.0" ?>
<!-- =================================================================================== -->
<!-- |    This document was autogenerated by xacro from crx10ia_l.xacro                | -->
<!-- |    EDITING THIS FILE BY HAND IS NOT RECOMMENDED                                 | -->
<!-- =================================================================================== -->
<robot name="crx10ia_l">
  <!-- Read only parameter should allow to move the robot via manual guidance, jog, etc throu the TP, and makes available the /joint_states topic -->
  <ros2_control name="crx10ia_l" type="system">
    <hardware>
      <plugin>mock_components/GenericSystem</plugin>
      <!-- <param name="position_state_following_offset">0.1</param> -->
    </hardware>
    <joint name="J1">
      <command_interface name="position">
        <param name="min">{-2*pi}</param>
        <param name="max">{2*pi}</param>
      </command_interface>
      <!-- <command_interface name="velocity">
          <param name="min">-3.15</param>
          <param name="max">3.15</param>
        </command_interface> -->
      <state_interface name="position">
        <param name="initial_value">0.0</param>
      </state_interface>
      <state_interface name="velocity"/>
    </joint>
    <joint name="J2">
      <command_interface name="position">
        <param name="min">{-2*pi}</param>
        <param name="max">{2*pi}</param>
      </command_interface>
      <!-- <command_interface name="velocity">
          <param name="min">-3.15</param>
          <param name="max">3.15</param>
        </command_interface> -->
      <state_interface name="position">
        <param name="initial_value">0.0</param>
      </state_interface>
      <state_interface name="velocity"/>
    </joint>
    <joint name="J3">
      <command_interface name="position">
        <param name="min">{-pi}</param>
        <param name="max">{pi}</param>
      </command_interface>
      <!-- <command_interface name="velocity">
          <param name="min">-3.15</param>
          <param name="max">3.15</param>
        </command_interface> -->
      <state_interface name="position">
        <param name="initial_value">0.0</param>
      </state_interface>
      <state_interface name="velocity"/>
    </joint>
    <joint name="J4">
      <command_interface name="position">
        <param name="min">{-2*pi}</param>
        <param name="max">{2*pi}</param>
      </command_interface>
      <!-- <command_interface name="velocity">
          <param name="min">-3.2</param>
          <param name="max">3.2</param>
        </command_interface> -->
      <state_interface name="position">
        <param name="initial_value">0.0</param>
      </state_interface>
      <state_interface name="velocity"/>
    </joint>
    <joint name="J5">
      <command_interface name="position">
        <param name="min">{-2*pi}</param>
        <param name="max">{2*pi}</param>
      </command_interface>
      <!-- <command_interface name="velocity">
          <param name="min">-3.2</param>
          <param name="max">3.2</param>
        </command_interface> -->
      <state_interface name="position">
        <param name="initial_value">0.0</param>
      </state_interface>
      <state_interface name="velocity"/>
    </joint>
    <joint name="J6">
      <command_interface name="position">
        <param name="min">{-2*pi}</param>
        <param name="max">{2*pi}</param>
      </command_interface>
      <!-- <command_interface name="velocity">
          <param name="min">-3.2</param>
          <param name="max">3.2</param>
        </command_interface> -->
      <state_interface name="position">
        <param name="initial_value">0.0</param>
      </state_interface>
      <state_interface name="velocity"/>
    </joint>
  </ros2_control>
  <material name="black">
    <color rgba="0 0 0 1.0"/>
  </material>
  <material name="white">
    <color rgba="1.0 1.0 1.0 1.00"/>
  </material>
  <!-- links -->
  <link name="base_link">
    <visual>
      <origin rpy="0 0 0" xyz="0 0 0"/>
      <geometry>
        <mesh filename="package://crx_description/meshes/crx10ia_l/visual/link_base.stl" scale="0.001 0.001 0.001"/>
      </geometry>
      <material name="black"/>
    </visual>
    <collision>
      <origin rpy="0 0 0" xyz="0 0 0"/>
      <geometry>
        <mesh filename="package://crx_description/meshes/crx10ia_l/collision/link_base.stl" scale="0.001 0.001 0.001"/>
      </geometry>
    </collision>
  </link>
  <link name="link_1">
    <visual>
      <origin rpy="0 0 0" xyz="0 0 0"/>
      <geometry>
        <mesh filename="package://crx_description/meshes/crx10ia_l/visual/link_1.stl" scale="0.001 0.001 0.001"/>
      </geometry>
      <material name="white"/>
    </visual>
    <collision>
      <origin rpy="0 0 0" xyz="0 0 0"/>
      <geometry>
        <mesh filename="package://crx_description/meshes/crx10ia_l/collision/link_1.stl" scale="0.001 0.001 0.001"/>
      </geometry>
    </collision>
  </link>
  <link name="link_2">
    <visual>
      <origin rpy="1.57 0 1.57" xyz="0 0 0"/>
      <geometry>
        <mesh filename="package://crx_description/meshes/crx10ia_l/visual/link_2.stl" scale="0.001 0.001 0.001"/>
      </geometry>
      <material name="white"/>
    </visual>
    <collision>
      <origin rpy="1.57 0 1.57" xyz="0 0 0"/>
      <geometry>
        <mesh filename="package://crx_description/meshes/crx10ia_l/collision/link_2.stl" scale="0.001 0.001 0.001"/>
      </geometry>
    </collision>
  </link>
  <link name="link_3">
    <visual>
      <origin rpy="1.57 0 1.57" xyz="0 0 0"/>
      <geometry>
        <mesh filename="package://crx_description/meshes/crx10ia_l/visual/link_3.stl" scale="0.001 0.001 0.001"/>
      </geometry>
      <material name="white"/>
    </visual>
    <collision>
      <origin rpy="1.57 0 0" xyz="0 0 0"/>
      <geometry>
        <mesh filename="package://crx_description/meshes/crx10ia_l/collision/link_3.stl" scale="0.001 0.001 0.001"/>
      </geometry>
    </collision>
  </link>
  <link name="link_4">
    <visual>
      <origin rpy="0 -1.57 -3.14" xyz="0 0 0"/>
      <geometry>
        <mesh filename="package://crx_description/meshes/crx10ia_l/visual/link_4.stl" scale="0.001 0.001 0.001"/>
      </geometry>
      <material name="white"/>
    </visual>
    <collision>
      <origin rpy="0 0 0" xyz="0 0 0"/>
      <geometry>
        <mesh filename="package://crx_description/meshes/crx10ia_l/collision/link_4.stl" scale="0.001 0.001 0.001"/>
      </geometry>
    </collision>
  </link>
  <link name="link_5">
    <visual>
      <origin rpy="0 -1.57 0" xyz="0 0 0"/>
      <geometry>
        <mesh filename="package://crx_description/meshes/crx10ia_l/visual/link_5.stl" scale="0.001 0.001 0.001"/>
      </geometry>
      <material name="white"/>
    </visual>
    <collision>
      <origin rpy="0 0 0" xyz="0 0 0"/>
      <geometry>
        <mesh filename="package://crx_description/meshes/crx10ia_l/collision/link_5.stl" scale="0.001 0.001 0.001"/>
      </geometry>
    </collision>
  </link>
  <link name="link_6">
    <visual>
      <origin rpy="0 -1.57 0" xyz="0 0 -0.015"/>
      <geometry>
        <mesh filename="package://crx_description/meshes/crx10ia_l/visual/link_6.stl" scale="0.001 0.001 0.001"/>
      </geometry>
      <material name="black"/>
    </visual>
    <collision>
      <origin rpy="0 0 0" xyz="0 0 0"/>
      <geometry>
        <mesh filename="package://crx_description/meshes/crx10ia_l/collision/link_6.stl" scale="0.001 0.001 0.001"/>
      </geometry>
    </collision>
  </link>
  <!-- joints -->
  <joint name="J1" type="revolute">
    <origin rpy="0 0 0" xyz="0 0 0.1277"/>
    <parent link="base_link"/>
    <child link="link_1"/>
    <axis xyz="0 0 1"/>
    <limit effort="0" lower="-3.141592653589793" upper="3.141592653589793" velocity="2.0943951023931953"/>
  </joint>
  <joint name="J2" type="revolute">
    <origin rpy="0 -1.57 -1.57" xyz="0 0 0.1173"/>
    <parent link="link_1"/>
    <child link="link_2"/>
    <axis xyz="0 0 1"/>
    <limit effort="0" lower="-3.141592653589793" upper="3.141592653589793" velocity="2.0943951023931953"/>
  </joint>
  <joint name="J3" type="revolute">
    <origin rpy="0 0 0" xyz="0.710 0 0"/>
    <parent link="link_2"/>
    <child link="link_3"/>
    <axis xyz="0 0 -1"/>
    <limit effort="0" lower="-4.71238898038469" upper="4.71238898038469" velocity="2.0943951023931953"/>
  </joint>
  <joint name="J4" type="revolute">
    <origin rpy="-1.57 0 0" xyz="0 0.540 0"/>
    <parent link="link_3"/>
    <child link="link_4"/>
    <axis xyz="0 0 -1"/>
    <limit effort="0" lower="-3.3161255787892263" upper="3.3161255787892263" velocity="1.9547687622336491"/>
  </joint>
  <joint name="J5" type="revolute">
    <origin rpy="1.57 0 0" xyz="0 0.150 0"/>
    <parent link="link_4"/>
    <child link="link_5"/>
    <axis xyz="0 0 -1"/>
    <limit effort="0" lower="-3.141592653589793" upper="3.141592653589793" velocity="1.5707963267948966"/>
  </joint>
  <joint name="J6" type="revolute">
    <origin rpy="-1.57 0 0" xyz="0 0.160 0"/>
    <parent link="link_5"/>
    <child link="link_6"/>
    <axis xyz="0 0 -1"/>
    <limit effort="0" lower="-3.9269908169872414" upper="3.9269908169872414" velocity="1.9547687622336491"/>
  </joint>
  <!-- fanuc world -->
  <link name="fanuc_world"/>
  <joint name="base_link-fanuc_world" type="fixed">
    <origin rpy="0 0 0" xyz="0 0 0.245"/>
    <parent link="base_link"/>
    <child link="fanuc_world"/>
  </joint>
  <!-- flange -->
  <link name="flange"/>
  <joint name="J6-flange" type="fixed">
    <origin rpy="0 0 0" xyz="0 0 0"/>
    <parent link="link_6"/>
    <child link="flange"/>
  </joint>
  <!-- tcp -->
  <link name="tcp"/>
  <joint name="flange-tcp" type="fixed">
    <origin rpy="0 1.5707963267948966 0" xyz="0 0 0"/>
    <parent link="flange"/>
    <child link="tcp"/>
  </joint>
</robot>
